[2025-04-10T15:08:07.710+0000] {local_task_job_runner.py:123} INFO - ::group::Pre task execution logs
[2025-04-10T15:08:08.254+0000] {taskinstance.py:2614} INFO - Dependencies all met for dep_context=non-requeueable deps ti=<TaskInstance: data_approval_dag.alert_rejection manual__2025-04-10T15:08:04.865854+00:00 [queued]>
[2025-04-10T15:08:08.301+0000] {taskinstance.py:2614} INFO - Dependencies all met for dep_context=requeueable deps ti=<TaskInstance: data_approval_dag.alert_rejection manual__2025-04-10T15:08:04.865854+00:00 [queued]>
[2025-04-10T15:08:08.302+0000] {taskinstance.py:2867} INFO - Starting attempt 1 of 1
[2025-04-10T15:08:08.362+0000] {taskinstance.py:2890} INFO - Executing <Task(PythonOperator): alert_rejection> on 2025-04-10 15:08:04.865854+00:00
[2025-04-10T15:08:08.424+0000] {warnings.py:112} WARNING - /home/***/.local/lib/python3.12/site-packages/***/task/task_runner/standard_task_runner.py:70: DeprecationWarning: This process (pid=1042) is multi-threaded, use of fork() may lead to deadlocks in the child.
  pid = os.fork()

[2025-04-10T15:08:08.426+0000] {standard_task_runner.py:72} INFO - Started process 1054 to run task
[2025-04-10T15:08:08.433+0000] {standard_task_runner.py:104} INFO - Running: ['***', 'tasks', 'run', 'data_approval_dag', 'alert_rejection', 'manual__2025-04-10T15:08:04.865854+00:00', '--job-id', '9', '--raw', '--subdir', 'DAGS_FOLDER/data_approval_dag.py', '--cfg-path', '/tmp/tmp7prtwz_7']
[2025-04-10T15:08:08.484+0000] {standard_task_runner.py:105} INFO - Job 9: Subtask alert_rejection
[2025-04-10T15:08:08.701+0000] {task_command.py:467} INFO - Running <TaskInstance: data_approval_dag.alert_rejection manual__2025-04-10T15:08:04.865854+00:00 [running]> on host 64d066c4d41c
[2025-04-10T15:08:08.889+0000] {taskinstance.py:3134} INFO - Exporting env vars: AIRFLOW_CTX_DAG_OWNER='***' AIRFLOW_CTX_DAG_ID='data_approval_dag' AIRFLOW_CTX_TASK_ID='alert_rejection' AIRFLOW_CTX_EXECUTION_DATE='2025-04-10T15:08:04.865854+00:00' AIRFLOW_CTX_TRY_NUMBER='1' AIRFLOW_CTX_DAG_RUN_ID='manual__2025-04-10T15:08:04.865854+00:00'
[2025-04-10T15:08:08.891+0000] {taskinstance.py:732} INFO - ::endgroup::
[2025-04-10T15:08:08.925+0000] {logging_mixin.py:190} INFO - Data has been rejected.
[2025-04-10T15:08:08.927+0000] {python.py:240} INFO - Done. Returned value was: None
[2025-04-10T15:08:08.953+0000] {taskinstance.py:341} INFO - ::group::Post task execution logs
[2025-04-10T15:08:08.957+0000] {taskinstance.py:353} INFO - Marking task as SUCCESS. dag_id=data_approval_dag, task_id=alert_rejection, run_id=manual__2025-04-10T15:08:04.865854+00:00, execution_date=20250410T150804, start_date=20250410T150808, end_date=20250410T150808
[2025-04-10T15:08:09.051+0000] {local_task_job_runner.py:266} INFO - Task exited with return code 0
[2025-04-10T15:08:09.134+0000] {taskinstance.py:3901} INFO - 0 downstream tasks scheduled from follow-on schedule check
[2025-04-10T15:08:09.139+0000] {local_task_job_runner.py:245} INFO - ::endgroup::
