[2025-04-10T13:51:03.041+0000] {local_task_job_runner.py:123} INFO - ::group::Pre task execution logs
[2025-04-10T13:51:03.121+0000] {taskinstance.py:2614} INFO - Dependencies all met for dep_context=non-requeueable deps ti=<TaskInstance: data_approval_dag.alert_rejection manual__2025-04-10T13:50:59.662162+00:00 [queued]>
[2025-04-10T13:51:03.171+0000] {taskinstance.py:2614} INFO - Dependencies all met for dep_context=requeueable deps ti=<TaskInstance: data_approval_dag.alert_rejection manual__2025-04-10T13:50:59.662162+00:00 [queued]>
[2025-04-10T13:51:03.182+0000] {taskinstance.py:2867} INFO - Starting attempt 1 of 1
[2025-04-10T13:51:03.277+0000] {taskinstance.py:2890} INFO - Executing <Task(PythonOperator): alert_rejection> on 2025-04-10 13:50:59.662162+00:00
[2025-04-10T13:51:03.295+0000] {warnings.py:112} WARNING - /home/***/.local/lib/python3.12/site-packages/***/task/task_runner/standard_task_runner.py:70: DeprecationWarning: This process (pid=103) is multi-threaded, use of fork() may lead to deadlocks in the child.
  pid = os.fork()

[2025-04-10T13:51:03.312+0000] {standard_task_runner.py:72} INFO - Started process 111 to run task
[2025-04-10T13:51:03.322+0000] {standard_task_runner.py:104} INFO - Running: ['***', 'tasks', 'run', 'data_approval_dag', 'alert_rejection', 'manual__2025-04-10T13:50:59.662162+00:00', '--job-id', '5', '--raw', '--subdir', 'DAGS_FOLDER/data_approval_dag.py', '--cfg-path', '/tmp/tmpr3139dae']
[2025-04-10T13:51:03.326+0000] {standard_task_runner.py:105} INFO - Job 5: Subtask alert_rejection
[2025-04-10T13:51:03.487+0000] {task_command.py:467} INFO - Running <TaskInstance: data_approval_dag.alert_rejection manual__2025-04-10T13:50:59.662162+00:00 [running]> on host 8e2e65f40186
[2025-04-10T13:51:03.803+0000] {taskinstance.py:3134} INFO - Exporting env vars: AIRFLOW_CTX_DAG_OWNER='***' AIRFLOW_CTX_DAG_ID='data_approval_dag' AIRFLOW_CTX_TASK_ID='alert_rejection' AIRFLOW_CTX_EXECUTION_DATE='2025-04-10T13:50:59.662162+00:00' AIRFLOW_CTX_TRY_NUMBER='1' AIRFLOW_CTX_DAG_RUN_ID='manual__2025-04-10T13:50:59.662162+00:00'
[2025-04-10T13:51:03.809+0000] {taskinstance.py:732} INFO - ::endgroup::
[2025-04-10T13:51:03.855+0000] {logging_mixin.py:190} INFO - Data has been rejected.
[2025-04-10T13:51:03.856+0000] {python.py:240} INFO - Done. Returned value was: None
[2025-04-10T13:51:03.876+0000] {taskinstance.py:341} INFO - ::group::Post task execution logs
[2025-04-10T13:51:03.877+0000] {taskinstance.py:353} INFO - Marking task as SUCCESS. dag_id=data_approval_dag, task_id=alert_rejection, run_id=manual__2025-04-10T13:50:59.662162+00:00, execution_date=20250410T135059, start_date=20250410T135103, end_date=20250410T135103
[2025-04-10T13:51:04.029+0000] {local_task_job_runner.py:266} INFO - Task exited with return code 0
[2025-04-10T13:51:04.082+0000] {taskinstance.py:3901} INFO - 0 downstream tasks scheduled from follow-on schedule check
[2025-04-10T13:51:04.091+0000] {local_task_job_runner.py:245} INFO - ::endgroup::
